[2025-03-28T20:35:31.415+0000] {taskinstance.py:1979} INFO - Dependencies all met for dep_context=non-requeueable deps ti=<TaskInstance: etl_arsenalfc.extract scheduled__2024-04-24T00:00:00+00:00 [queued]>
[2025-03-28T20:35:31.433+0000] {taskinstance.py:1979} INFO - Dependencies all met for dep_context=requeueable deps ti=<TaskInstance: etl_arsenalfc.extract scheduled__2024-04-24T00:00:00+00:00 [queued]>
[2025-03-28T20:35:31.434+0000] {taskinstance.py:2193} INFO - Starting attempt 1 of 2
[2025-03-28T20:35:31.541+0000] {taskinstance.py:2217} INFO - Executing <Task(BashOperator): extract> on 2024-04-24 00:00:00+00:00
[2025-03-28T20:35:31.556+0000] {standard_task_runner.py:60} INFO - Started process 1902 to run task
[2025-03-28T20:35:31.561+0000] {standard_task_runner.py:87} INFO - Running: ['***', 'tasks', 'run', 'etl_arsenalfc', 'extract', 'scheduled__2024-04-24T00:00:00+00:00', '--job-id', '75', '--raw', '--subdir', 'DAGS_FOLDER/ArsenalDag.py', '--cfg-path', '/tmp/tmpm342e963']
[2025-03-28T20:35:31.564+0000] {standard_task_runner.py:88} INFO - Job 75: Subtask extract
[2025-03-28T20:35:31.589+0000] {logging_mixin.py:188} WARNING - /home/***/.local/lib/python3.8/site-packages/***/settings.py:194 DeprecationWarning: The sql_alchemy_conn option in [core] has been moved to the sql_alchemy_conn option in [database] - the old setting has been used, but please update your config.
[2025-03-28T20:35:31.690+0000] {task_command.py:423} INFO - Running <TaskInstance: etl_arsenalfc.extract scheduled__2024-04-24T00:00:00+00:00 [running]> on host d87fcbd51e2e
[2025-03-28T20:35:31.865+0000] {taskinstance.py:2513} INFO - Exporting env vars: AIRFLOW_CTX_DAG_OWNER='***' AIRFLOW_CTX_DAG_ID='etl_arsenalfc' AIRFLOW_CTX_TASK_ID='extract' AIRFLOW_CTX_EXECUTION_DATE='2024-04-24T00:00:00+00:00' AIRFLOW_CTX_TRY_NUMBER='1' AIRFLOW_CTX_DAG_RUN_ID='scheduled__2024-04-24T00:00:00+00:00'
[2025-03-28T20:35:31.867+0000] {subprocess.py:63} INFO - Tmp dir root location: /tmp
[2025-03-28T20:35:31.868+0000] {subprocess.py:75} INFO - Running command: ['/usr/bin/bash', '-c', 'spark-submit --jars /Drivers/SQL_Sever/jdbc/postgresql-42.7.3.jar /opt/***/spark/app/extract.py']
[2025-03-28T20:35:31.940+0000] {subprocess.py:86} INFO - Output:
[2025-03-28T20:35:32.092+0000] {subprocess.py:93} INFO - /home/***/.local/lib/python3.8/site-packages/pyspark/bin/load-spark-env.sh: line 68: ps: command not found
[2025-03-28T20:35:38.618+0000] {subprocess.py:93} INFO - 25/03/28 20:35:38 WARN NativeCodeLoader: Unable to load native-hadoop library for your platform... using builtin-java classes where applicable
[2025-03-28T20:35:39.338+0000] {subprocess.py:93} INFO - python3: can't open file '/opt/***/spark/app/extract.py': [Errno 2] No such file or directory
[2025-03-28T20:35:39.360+0000] {subprocess.py:93} INFO - 25/03/28 20:35:39 INFO ShutdownHookManager: Shutdown hook called
[2025-03-28T20:35:39.363+0000] {subprocess.py:93} INFO - 25/03/28 20:35:39 INFO ShutdownHookManager: Deleting directory /tmp/spark-0deaab92-b4eb-4ae7-93c1-746e004efa33
[2025-03-28T20:35:39.459+0000] {subprocess.py:97} INFO - Command exited with return code 2
[2025-03-28T20:35:39.488+0000] {taskinstance.py:2731} ERROR - Task failed with exception
Traceback (most recent call last):
  File "/home/airflow/.local/lib/python3.8/site-packages/airflow/models/taskinstance.py", line 444, in _execute_task
    result = _execute_callable(context=context, **execute_callable_kwargs)
  File "/home/airflow/.local/lib/python3.8/site-packages/airflow/models/taskinstance.py", line 414, in _execute_callable
    return execute_callable(context=context, **execute_callable_kwargs)
  File "/home/airflow/.local/lib/python3.8/site-packages/airflow/operators/bash.py", line 212, in execute
    raise AirflowException(
airflow.exceptions.AirflowException: Bash command failed. The command returned a non-zero exit code 2.
[2025-03-28T20:35:39.501+0000] {taskinstance.py:1149} INFO - Marking task as UP_FOR_RETRY. dag_id=etl_arsenalfc, task_id=extract, execution_date=20240424T000000, start_date=20250328T203531, end_date=20250328T203539
[2025-03-28T20:35:39.533+0000] {standard_task_runner.py:107} ERROR - Failed to execute job 75 for task extract (Bash command failed. The command returned a non-zero exit code 2.; 1902)
[2025-03-28T20:35:39.555+0000] {local_task_job_runner.py:234} INFO - Task exited with return code 1
[2025-03-28T20:35:39.596+0000] {taskinstance.py:3312} INFO - 0 downstream tasks scheduled from follow-on schedule check
