[2025-03-28T20:30:11.943+0000] {taskinstance.py:1979} INFO - Dependencies all met for dep_context=non-requeueable deps ti=<TaskInstance: etl_arsenalfc.extract scheduled__2024-04-08T00:00:00+00:00 [queued]>
[2025-03-28T20:30:11.960+0000] {taskinstance.py:1979} INFO - Dependencies all met for dep_context=requeueable deps ti=<TaskInstance: etl_arsenalfc.extract scheduled__2024-04-08T00:00:00+00:00 [queued]>
[2025-03-28T20:30:11.960+0000] {taskinstance.py:2193} INFO - Starting attempt 1 of 2
[2025-03-28T20:30:12.027+0000] {taskinstance.py:2217} INFO - Executing <Task(BashOperator): extract> on 2024-04-08 00:00:00+00:00
[2025-03-28T20:30:12.041+0000] {standard_task_runner.py:60} INFO - Started process 2715 to run task
[2025-03-28T20:30:12.047+0000] {standard_task_runner.py:87} INFO - Running: ['***', 'tasks', 'run', 'etl_arsenalfc', 'extract', 'scheduled__2024-04-08T00:00:00+00:00', '--job-id', '42', '--raw', '--subdir', 'DAGS_FOLDER/ArsenalDag.py', '--cfg-path', '/tmp/tmpkp0zf4at']
[2025-03-28T20:30:12.050+0000] {standard_task_runner.py:88} INFO - Job 42: Subtask extract
[2025-03-28T20:30:12.080+0000] {logging_mixin.py:188} WARNING - /home/***/.local/lib/python3.8/site-packages/***/settings.py:194 DeprecationWarning: The sql_alchemy_conn option in [core] has been moved to the sql_alchemy_conn option in [database] - the old setting has been used, but please update your config.
[2025-03-28T20:30:12.155+0000] {task_command.py:423} INFO - Running <TaskInstance: etl_arsenalfc.extract scheduled__2024-04-08T00:00:00+00:00 [running]> on host d87fcbd51e2e
[2025-03-28T20:30:12.318+0000] {taskinstance.py:2513} INFO - Exporting env vars: AIRFLOW_CTX_DAG_OWNER='***' AIRFLOW_CTX_DAG_ID='etl_arsenalfc' AIRFLOW_CTX_TASK_ID='extract' AIRFLOW_CTX_EXECUTION_DATE='2024-04-08T00:00:00+00:00' AIRFLOW_CTX_TRY_NUMBER='1' AIRFLOW_CTX_DAG_RUN_ID='scheduled__2024-04-08T00:00:00+00:00'
[2025-03-28T20:30:12.321+0000] {subprocess.py:63} INFO - Tmp dir root location: /tmp
[2025-03-28T20:30:12.324+0000] {subprocess.py:75} INFO - Running command: ['/usr/bin/bash', '-c', 'spark-submit --jars /Drivers/SQL_Sever/jdbc/postgresql-42.7.3.jar /opt/***/spark/app/extract.py']
[2025-03-28T20:30:12.356+0000] {subprocess.py:86} INFO - Output:
[2025-03-28T20:30:12.524+0000] {subprocess.py:93} INFO - /home/***/.local/lib/python3.8/site-packages/pyspark/bin/load-spark-env.sh: line 68: ps: command not found
[2025-03-28T20:30:18.503+0000] {subprocess.py:93} INFO - 25/03/28 20:30:18 WARN NativeCodeLoader: Unable to load native-hadoop library for your platform... using builtin-java classes where applicable
[2025-03-28T20:30:19.366+0000] {subprocess.py:93} INFO - python3: can't open file '/opt/***/spark/app/extract.py': [Errno 2] No such file or directory
[2025-03-28T20:30:19.400+0000] {subprocess.py:93} INFO - 25/03/28 20:30:19 INFO ShutdownHookManager: Shutdown hook called
[2025-03-28T20:30:19.404+0000] {subprocess.py:93} INFO - 25/03/28 20:30:19 INFO ShutdownHookManager: Deleting directory /tmp/spark-de05d455-5c43-4fa5-99d0-c5ce2c726621
[2025-03-28T20:30:19.504+0000] {subprocess.py:97} INFO - Command exited with return code 2
[2025-03-28T20:30:19.525+0000] {taskinstance.py:2731} ERROR - Task failed with exception
Traceback (most recent call last):
  File "/home/airflow/.local/lib/python3.8/site-packages/airflow/models/taskinstance.py", line 444, in _execute_task
    result = _execute_callable(context=context, **execute_callable_kwargs)
  File "/home/airflow/.local/lib/python3.8/site-packages/airflow/models/taskinstance.py", line 414, in _execute_callable
    return execute_callable(context=context, **execute_callable_kwargs)
  File "/home/airflow/.local/lib/python3.8/site-packages/airflow/operators/bash.py", line 212, in execute
    raise AirflowException(
airflow.exceptions.AirflowException: Bash command failed. The command returned a non-zero exit code 2.
[2025-03-28T20:30:19.531+0000] {taskinstance.py:1149} INFO - Marking task as UP_FOR_RETRY. dag_id=etl_arsenalfc, task_id=extract, execution_date=20240408T000000, start_date=20250328T203011, end_date=20250328T203019
[2025-03-28T20:30:19.558+0000] {standard_task_runner.py:107} ERROR - Failed to execute job 42 for task extract (Bash command failed. The command returned a non-zero exit code 2.; 2715)
[2025-03-28T20:30:19.590+0000] {local_task_job_runner.py:234} INFO - Task exited with return code 1
[2025-03-28T20:30:19.623+0000] {taskinstance.py:3312} INFO - 0 downstream tasks scheduled from follow-on schedule check
