[2025-03-28T20:30:11.545+0000] {taskinstance.py:1979} INFO - Dependencies all met for dep_context=non-requeueable deps ti=<TaskInstance: etl_arsenalfc.extract scheduled__2024-04-05T00:00:00+00:00 [queued]>
[2025-03-28T20:30:11.557+0000] {taskinstance.py:1979} INFO - Dependencies all met for dep_context=requeueable deps ti=<TaskInstance: etl_arsenalfc.extract scheduled__2024-04-05T00:00:00+00:00 [queued]>
[2025-03-28T20:30:11.557+0000] {taskinstance.py:2193} INFO - Starting attempt 1 of 2
[2025-03-28T20:30:11.570+0000] {taskinstance.py:2217} INFO - Executing <Task(BashOperator): extract> on 2024-04-05 00:00:00+00:00
[2025-03-28T20:30:11.578+0000] {standard_task_runner.py:60} INFO - Started process 2514 to run task
[2025-03-28T20:30:11.582+0000] {standard_task_runner.py:87} INFO - Running: ['***', 'tasks', 'run', 'etl_arsenalfc', 'extract', 'scheduled__2024-04-05T00:00:00+00:00', '--job-id', '39', '--raw', '--subdir', 'DAGS_FOLDER/ArsenalDag.py', '--cfg-path', '/tmp/tmpfwgvmumo']
[2025-03-28T20:30:11.584+0000] {standard_task_runner.py:88} INFO - Job 39: Subtask extract
[2025-03-28T20:30:11.604+0000] {logging_mixin.py:188} WARNING - /home/***/.local/lib/python3.8/site-packages/***/settings.py:194 DeprecationWarning: The sql_alchemy_conn option in [core] has been moved to the sql_alchemy_conn option in [database] - the old setting has been used, but please update your config.
[2025-03-28T20:30:11.649+0000] {task_command.py:423} INFO - Running <TaskInstance: etl_arsenalfc.extract scheduled__2024-04-05T00:00:00+00:00 [running]> on host d87fcbd51e2e
[2025-03-28T20:30:11.752+0000] {taskinstance.py:2513} INFO - Exporting env vars: AIRFLOW_CTX_DAG_OWNER='***' AIRFLOW_CTX_DAG_ID='etl_arsenalfc' AIRFLOW_CTX_TASK_ID='extract' AIRFLOW_CTX_EXECUTION_DATE='2024-04-05T00:00:00+00:00' AIRFLOW_CTX_TRY_NUMBER='1' AIRFLOW_CTX_DAG_RUN_ID='scheduled__2024-04-05T00:00:00+00:00'
[2025-03-28T20:30:11.754+0000] {subprocess.py:63} INFO - Tmp dir root location: /tmp
[2025-03-28T20:30:11.756+0000] {subprocess.py:75} INFO - Running command: ['/usr/bin/bash', '-c', 'spark-submit --jars /Drivers/SQL_Sever/jdbc/postgresql-42.7.3.jar /opt/***/spark/app/extract.py']
[2025-03-28T20:30:11.775+0000] {subprocess.py:86} INFO - Output:
[2025-03-28T20:30:11.832+0000] {subprocess.py:93} INFO - /home/***/.local/lib/python3.8/site-packages/pyspark/bin/load-spark-env.sh: line 68: ps: command not found
[2025-03-28T20:30:17.802+0000] {subprocess.py:93} INFO - 25/03/28 20:30:17 WARN NativeCodeLoader: Unable to load native-hadoop library for your platform... using builtin-java classes where applicable
[2025-03-28T20:30:18.993+0000] {subprocess.py:93} INFO - python3: can't open file '/opt/***/spark/app/extract.py': [Errno 2] No such file or directory
[2025-03-28T20:30:19.025+0000] {subprocess.py:93} INFO - 25/03/28 20:30:19 INFO ShutdownHookManager: Shutdown hook called
[2025-03-28T20:30:19.028+0000] {subprocess.py:93} INFO - 25/03/28 20:30:19 INFO ShutdownHookManager: Deleting directory /tmp/spark-bc9fa10a-bdff-4c20-9e3f-b6cfca3ea48a
[2025-03-28T20:30:19.140+0000] {subprocess.py:97} INFO - Command exited with return code 2
[2025-03-28T20:30:19.160+0000] {taskinstance.py:2731} ERROR - Task failed with exception
Traceback (most recent call last):
  File "/home/airflow/.local/lib/python3.8/site-packages/airflow/models/taskinstance.py", line 444, in _execute_task
    result = _execute_callable(context=context, **execute_callable_kwargs)
  File "/home/airflow/.local/lib/python3.8/site-packages/airflow/models/taskinstance.py", line 414, in _execute_callable
    return execute_callable(context=context, **execute_callable_kwargs)
  File "/home/airflow/.local/lib/python3.8/site-packages/airflow/operators/bash.py", line 212, in execute
    raise AirflowException(
airflow.exceptions.AirflowException: Bash command failed. The command returned a non-zero exit code 2.
[2025-03-28T20:30:19.166+0000] {taskinstance.py:1149} INFO - Marking task as UP_FOR_RETRY. dag_id=etl_arsenalfc, task_id=extract, execution_date=20240405T000000, start_date=20250328T203011, end_date=20250328T203019
[2025-03-28T20:30:19.192+0000] {standard_task_runner.py:107} ERROR - Failed to execute job 39 for task extract (Bash command failed. The command returned a non-zero exit code 2.; 2514)
[2025-03-28T20:30:19.249+0000] {local_task_job_runner.py:234} INFO - Task exited with return code 1
[2025-03-28T20:30:19.292+0000] {taskinstance.py:3312} INFO - 0 downstream tasks scheduled from follow-on schedule check
