[2025-03-28T21:07:01.445+0000] {taskinstance.py:1979} INFO - Dependencies all met for dep_context=non-requeueable deps ti=<TaskInstance: etl_arsenalfc.extract __airflow_temporary_run_2025-03-28T21:07:00.414197+00:00__ [queued]>
[2025-03-28T21:07:01.457+0000] {taskinstance.py:1979} INFO - Dependencies all met for dep_context=requeueable deps ti=<TaskInstance: etl_arsenalfc.extract __airflow_temporary_run_2025-03-28T21:07:00.414197+00:00__ [queued]>
[2025-03-28T21:07:01.457+0000] {taskinstance.py:2193} INFO - Starting attempt 1 of 2
[2025-03-28T21:07:01.589+0000] {taskinstance.py:2217} INFO - Executing <Task(SparkSubmitOperator): extract> on 2025-03-28 21:07:00.414151+00:00
[2025-03-28T21:07:01.597+0000] {standard_task_runner.py:60} INFO - Started process 617 to run task
[2025-03-28T21:07:01.602+0000] {standard_task_runner.py:87} INFO - Running: ['***', 'tasks', 'run', 'etl_arsenalfc', 'extract', '__***_temporary_run_2025-03-28T21:07:00.414197+00:00__', '--job-id', '248', '--raw', '--subdir', 'DAGS_FOLDER/ArsenalDag.py', '--cfg-path', '/tmp/tmpenz7oz6x']
[2025-03-28T21:07:01.605+0000] {standard_task_runner.py:88} INFO - Job 248: Subtask extract
[2025-03-28T21:07:01.626+0000] {logging_mixin.py:188} WARNING - /home/***/.local/lib/python3.8/site-packages/***/settings.py:194 DeprecationWarning: The sql_alchemy_conn option in [core] has been moved to the sql_alchemy_conn option in [database] - the old setting has been used, but please update your config.
[2025-03-28T21:07:01.679+0000] {task_command.py:423} INFO - Running <TaskInstance: etl_arsenalfc.extract __airflow_temporary_run_2025-03-28T21:07:00.414197+00:00__ [running]> on host d87fcbd51e2e
[2025-03-28T21:07:01.790+0000] {taskinstance.py:2513} INFO - Exporting env vars: AIRFLOW_CTX_DAG_OWNER='***' AIRFLOW_CTX_DAG_ID='etl_arsenalfc' AIRFLOW_CTX_TASK_ID='extract' AIRFLOW_CTX_EXECUTION_DATE='2025-03-28T21:07:00.414151+00:00' AIRFLOW_CTX_TRY_NUMBER='1' AIRFLOW_CTX_DAG_RUN_ID='__***_temporary_run_2025-03-28T21:07:00.414197+00:00__'
[2025-03-28T21:07:01.804+0000] {base.py:83} INFO - Using connection ID 'spark_conn' for task execution.
[2025-03-28T21:07:01.806+0000] {spark_submit.py:335} INFO - Spark-Submit cmd: spark-submit --master spark:7077 --jars /Drivers/SQL_Sever/jdbc/postgresql-42.7.3.jar --name arrow-spark /opt/spark/app/Extract.py
[2025-03-28T21:07:01.893+0000] {spark_submit.py:488} INFO - /home/***/.local/lib/python3.8/site-packages/pyspark/bin/load-spark-env.sh: line 68: ps: command not found
[2025-03-28T21:07:03.969+0000] {spark_submit.py:488} INFO - 25/03/28 21:07:03 WARN NativeCodeLoader: Unable to load native-hadoop library for your platform... using builtin-java classes where applicable
[2025-03-28T21:07:04.250+0000] {spark_submit.py:488} INFO - python3: can't open file '/opt/spark/app/Extract.py': [Errno 2] No such file or directory
[2025-03-28T21:07:04.260+0000] {spark_submit.py:488} INFO - 25/03/28 21:07:04 INFO ShutdownHookManager: Shutdown hook called
[2025-03-28T21:07:04.260+0000] {spark_submit.py:488} INFO - 25/03/28 21:07:04 INFO ShutdownHookManager: Deleting directory /tmp/spark-594a5fc3-6ba0-4531-b9a4-0d97baddbaef
[2025-03-28T21:07:04.318+0000] {taskinstance.py:2731} ERROR - Task failed with exception
Traceback (most recent call last):
  File "/home/airflow/.local/lib/python3.8/site-packages/airflow/models/taskinstance.py", line 444, in _execute_task
    result = _execute_callable(context=context, **execute_callable_kwargs)
  File "/home/airflow/.local/lib/python3.8/site-packages/airflow/models/taskinstance.py", line 414, in _execute_callable
    return execute_callable(context=context, **execute_callable_kwargs)
  File "/home/airflow/.local/lib/python3.8/site-packages/airflow/providers/apache/spark/operators/spark_submit.py", line 157, in execute
    self._hook.submit(self._application)
  File "/home/airflow/.local/lib/python3.8/site-packages/airflow/providers/apache/spark/hooks/spark_submit.py", line 419, in submit
    raise AirflowException(
airflow.exceptions.AirflowException: Cannot execute: spark-submit --master spark:7077 --jars /Drivers/SQL_Sever/jdbc/postgresql-42.7.3.jar --name arrow-spark /opt/spark/app/Extract.py. Error code is: 2.
[2025-03-28T21:07:04.321+0000] {taskinstance.py:1149} INFO - Marking task as FAILED. dag_id=etl_arsenalfc, task_id=extract, execution_date=20250328T210700, start_date=20250328T210701, end_date=20250328T210704
[2025-03-28T21:07:04.335+0000] {standard_task_runner.py:107} ERROR - Failed to execute job 248 for task extract ((psycopg2.errors.ForeignKeyViolation) insert or update on table "task_fail" violates foreign key constraint "task_fail_ti_fkey"
DETAIL:  Key (dag_id, task_id, run_id, map_index)=(etl_arsenalfc, extract, __airflow_temporary_run_2025-03-28T21:07:00.414197+00:00__, -1) is not present in table "task_instance".

[SQL: INSERT INTO task_fail (task_id, dag_id, run_id, map_index, start_date, end_date, duration) VALUES (%(task_id)s, %(dag_id)s, %(run_id)s, %(map_index)s, %(start_date)s, %(end_date)s, %(duration)s) RETURNING task_fail.id]
[parameters: {'task_id': 'extract', 'dag_id': 'etl_arsenalfc', 'run_id': '__airflow_temporary_run_2025-03-28T21:07:00.414197+00:00__', 'map_index': -1, 'start_date': datetime.datetime(2025, 3, 28, 21, 7, 1, 446054, tzinfo=Timezone('UTC')), 'end_date': datetime.datetime(2025, 3, 28, 21, 7, 4, 321183, tzinfo=Timezone('UTC')), 'duration': 2}]
(Background on this error at: https://sqlalche.me/e/14/gkpj); 617)
[2025-03-28T21:07:04.383+0000] {local_task_job_runner.py:234} INFO - Task exited with return code 1
