[2025-03-28T21:19:11.677+0000] {taskinstance.py:1979} INFO - Dependencies all met for dep_context=non-requeueable deps ti=<TaskInstance: etl_arsenalfc.extract __airflow_temporary_run_2025-03-28T21:19:11.169959+00:00__ [queued]>
[2025-03-28T21:19:11.687+0000] {taskinstance.py:1979} INFO - Dependencies all met for dep_context=requeueable deps ti=<TaskInstance: etl_arsenalfc.extract __airflow_temporary_run_2025-03-28T21:19:11.169959+00:00__ [queued]>
[2025-03-28T21:19:11.687+0000] {taskinstance.py:2193} INFO - Starting attempt 1 of 2
[2025-03-28T21:19:11.705+0000] {taskinstance.py:2217} INFO - Executing <Task(SparkSubmitOperator): extract> on 2025-03-28 21:19:11.169914+00:00
[2025-03-28T21:19:11.714+0000] {standard_task_runner.py:60} INFO - Started process 3564 to run task
[2025-03-28T21:19:11.719+0000] {standard_task_runner.py:87} INFO - Running: ['***', 'tasks', 'run', 'etl_arsenalfc', 'extract', '__***_temporary_run_2025-03-28T21:19:11.169959+00:00__', '--job-id', '271', '--raw', '--subdir', 'DAGS_FOLDER/ArsenalDag.py', '--cfg-path', '/tmp/tmpxeectdq0']
[2025-03-28T21:19:11.721+0000] {standard_task_runner.py:88} INFO - Job 271: Subtask extract
[2025-03-28T21:19:11.741+0000] {logging_mixin.py:188} WARNING - /home/***/.local/lib/python3.8/site-packages/***/settings.py:194 DeprecationWarning: The sql_alchemy_conn option in [core] has been moved to the sql_alchemy_conn option in [database] - the old setting has been used, but please update your config.
[2025-03-28T21:19:11.790+0000] {task_command.py:423} INFO - Running <TaskInstance: etl_arsenalfc.extract __airflow_temporary_run_2025-03-28T21:19:11.169959+00:00__ [running]> on host d87fcbd51e2e
[2025-03-28T21:19:11.900+0000] {taskinstance.py:2513} INFO - Exporting env vars: AIRFLOW_CTX_DAG_OWNER='***' AIRFLOW_CTX_DAG_ID='etl_arsenalfc' AIRFLOW_CTX_TASK_ID='extract' AIRFLOW_CTX_EXECUTION_DATE='2025-03-28T21:19:11.169914+00:00' AIRFLOW_CTX_TRY_NUMBER='1' AIRFLOW_CTX_DAG_RUN_ID='__***_temporary_run_2025-03-28T21:19:11.169959+00:00__'
[2025-03-28T21:19:11.913+0000] {base.py:83} INFO - Using connection ID 'spark_conn' for task execution.
[2025-03-28T21:19:11.915+0000] {spark_submit.py:335} INFO - Spark-Submit cmd: spark-submit --master spark:7077 --jars /Drivers/SQL_Sever/jdbc/postgresql-42.7.3.jar --name arrow-spark /opt/bitnami/spark/app/Extract.py
[2025-03-28T21:19:11.992+0000] {spark_submit.py:488} INFO - /home/***/.local/lib/python3.8/site-packages/pyspark/bin/load-spark-env.sh: line 68: ps: command not found
[2025-03-28T21:19:14.096+0000] {spark_submit.py:488} INFO - 25/03/28 21:19:14 WARN NativeCodeLoader: Unable to load native-hadoop library for your platform... using builtin-java classes where applicable
[2025-03-28T21:19:14.452+0000] {spark_submit.py:488} INFO - python3: can't open file '/opt/bitnami/spark/app/Extract.py': [Errno 2] No such file or directory
[2025-03-28T21:19:14.466+0000] {spark_submit.py:488} INFO - 25/03/28 21:19:14 INFO ShutdownHookManager: Shutdown hook called
[2025-03-28T21:19:14.467+0000] {spark_submit.py:488} INFO - 25/03/28 21:19:14 INFO ShutdownHookManager: Deleting directory /tmp/spark-6f3f7c1c-34f0-4d86-9be0-cbcfef72fd50
[2025-03-28T21:19:14.537+0000] {taskinstance.py:2731} ERROR - Task failed with exception
Traceback (most recent call last):
  File "/home/airflow/.local/lib/python3.8/site-packages/airflow/models/taskinstance.py", line 444, in _execute_task
    result = _execute_callable(context=context, **execute_callable_kwargs)
  File "/home/airflow/.local/lib/python3.8/site-packages/airflow/models/taskinstance.py", line 414, in _execute_callable
    return execute_callable(context=context, **execute_callable_kwargs)
  File "/home/airflow/.local/lib/python3.8/site-packages/airflow/providers/apache/spark/operators/spark_submit.py", line 157, in execute
    self._hook.submit(self._application)
  File "/home/airflow/.local/lib/python3.8/site-packages/airflow/providers/apache/spark/hooks/spark_submit.py", line 419, in submit
    raise AirflowException(
airflow.exceptions.AirflowException: Cannot execute: spark-submit --master spark:7077 --jars /Drivers/SQL_Sever/jdbc/postgresql-42.7.3.jar --name arrow-spark /opt/bitnami/spark/app/Extract.py. Error code is: 2.
[2025-03-28T21:19:14.541+0000] {taskinstance.py:1149} INFO - Marking task as FAILED. dag_id=etl_arsenalfc, task_id=extract, execution_date=20250328T211911, start_date=20250328T211911, end_date=20250328T211914
[2025-03-28T21:19:14.559+0000] {standard_task_runner.py:107} ERROR - Failed to execute job 271 for task extract ((psycopg2.errors.ForeignKeyViolation) insert or update on table "task_fail" violates foreign key constraint "task_fail_ti_fkey"
DETAIL:  Key (dag_id, task_id, run_id, map_index)=(etl_arsenalfc, extract, __airflow_temporary_run_2025-03-28T21:19:11.169959+00:00__, -1) is not present in table "task_instance".

[SQL: INSERT INTO task_fail (task_id, dag_id, run_id, map_index, start_date, end_date, duration) VALUES (%(task_id)s, %(dag_id)s, %(run_id)s, %(map_index)s, %(start_date)s, %(end_date)s, %(duration)s) RETURNING task_fail.id]
[parameters: {'task_id': 'extract', 'dag_id': 'etl_arsenalfc', 'run_id': '__airflow_temporary_run_2025-03-28T21:19:11.169959+00:00__', 'map_index': -1, 'start_date': datetime.datetime(2025, 3, 28, 21, 19, 11, 677936, tzinfo=Timezone('UTC')), 'end_date': datetime.datetime(2025, 3, 28, 21, 19, 14, 540507, tzinfo=Timezone('UTC')), 'duration': 2}]
(Background on this error at: https://sqlalche.me/e/14/gkpj); 3564)
[2025-03-28T21:19:14.580+0000] {local_task_job_runner.py:234} INFO - Task exited with return code 1
