[2025-03-29T08:43:59.888+0000] {taskinstance.py:1979} INFO - Dependencies all met for dep_context=non-requeueable deps ti=<TaskInstance: etl_arsenalfc.extract scheduled__2024-07-26T00:00:00+00:00 [queued]>
[2025-03-29T08:43:59.900+0000] {taskinstance.py:1979} INFO - Dependencies all met for dep_context=requeueable deps ti=<TaskInstance: etl_arsenalfc.extract scheduled__2024-07-26T00:00:00+00:00 [queued]>
[2025-03-29T08:43:59.901+0000] {taskinstance.py:2193} INFO - Starting attempt 2 of 2
[2025-03-29T08:44:00.064+0000] {taskinstance.py:2217} INFO - Executing <Task(BashOperator): extract> on 2024-07-26 00:00:00+00:00
[2025-03-29T08:44:00.072+0000] {standard_task_runner.py:60} INFO - Started process 421 to run task
[2025-03-29T08:44:00.078+0000] {standard_task_runner.py:87} INFO - Running: ['***', 'tasks', 'run', 'etl_arsenalfc', 'extract', 'scheduled__2024-07-26T00:00:00+00:00', '--job-id', '295', '--raw', '--subdir', 'DAGS_FOLDER/ArsenalDag.py', '--cfg-path', '/tmp/tmpsvx5g2l0']
[2025-03-29T08:44:00.081+0000] {standard_task_runner.py:88} INFO - Job 295: Subtask extract
[2025-03-29T08:44:00.104+0000] {logging_mixin.py:188} WARNING - /home/***/.local/lib/python3.8/site-packages/***/settings.py:194 DeprecationWarning: The sql_alchemy_conn option in [core] has been moved to the sql_alchemy_conn option in [database] - the old setting has been used, but please update your config.
[2025-03-29T08:44:00.164+0000] {task_command.py:423} INFO - Running <TaskInstance: etl_arsenalfc.extract scheduled__2024-07-26T00:00:00+00:00 [running]> on host 0885a72a0a09
[2025-03-29T08:44:00.282+0000] {taskinstance.py:2513} INFO - Exporting env vars: AIRFLOW_CTX_DAG_OWNER='***' AIRFLOW_CTX_DAG_ID='etl_arsenalfc' AIRFLOW_CTX_TASK_ID='extract' AIRFLOW_CTX_EXECUTION_DATE='2024-07-26T00:00:00+00:00' AIRFLOW_CTX_TRY_NUMBER='2' AIRFLOW_CTX_DAG_RUN_ID='scheduled__2024-07-26T00:00:00+00:00'
[2025-03-29T08:44:00.283+0000] {subprocess.py:63} INFO - Tmp dir root location: /tmp
[2025-03-29T08:44:00.284+0000] {subprocess.py:75} INFO - Running command: ['/usr/bin/bash', '-c', 'spark-submit --jars /Drivers/SQL_Sever/jdbc/postgresql-42.7.3.jar /opt/***/spark/app/extract.py']
[2025-03-29T08:44:00.303+0000] {subprocess.py:86} INFO - Output:
[2025-03-29T08:44:00.315+0000] {subprocess.py:93} INFO - /home/***/.local/bin/spark-submit: line 27: /usr/local/lib/python3.8/site-packages/pyspark/bin/spark-class: No such file or directory
[2025-03-29T08:44:00.315+0000] {subprocess.py:97} INFO - Command exited with return code 127
[2025-03-29T08:44:00.336+0000] {taskinstance.py:2731} ERROR - Task failed with exception
Traceback (most recent call last):
  File "/home/airflow/.local/lib/python3.8/site-packages/airflow/models/taskinstance.py", line 444, in _execute_task
    result = _execute_callable(context=context, **execute_callable_kwargs)
  File "/home/airflow/.local/lib/python3.8/site-packages/airflow/models/taskinstance.py", line 414, in _execute_callable
    return execute_callable(context=context, **execute_callable_kwargs)
  File "/home/airflow/.local/lib/python3.8/site-packages/airflow/operators/bash.py", line 212, in execute
    raise AirflowException(
airflow.exceptions.AirflowException: Bash command failed. The command returned a non-zero exit code 127.
[2025-03-29T08:44:00.341+0000] {taskinstance.py:1149} INFO - Marking task as FAILED. dag_id=etl_arsenalfc, task_id=extract, execution_date=20240726T000000, start_date=20250329T084359, end_date=20250329T084400
[2025-03-29T08:44:00.363+0000] {standard_task_runner.py:107} ERROR - Failed to execute job 295 for task extract (Bash command failed. The command returned a non-zero exit code 127.; 421)
[2025-03-29T08:44:00.411+0000] {local_task_job_runner.py:234} INFO - Task exited with return code 1
[2025-03-29T08:44:00.445+0000] {taskinstance.py:3312} INFO - 0 downstream tasks scheduled from follow-on schedule check
